Workbook

Sheet Dashboard
A1: Granite OpenVINO Experimental Fork - Results Dashboard
A3: Validated campaign fv6 | Sector Experience Quality v3 | Healthcare + Education | 2026-08-30
A5: Planned cases | D5: Executed cases | G5: Unavailable | J5: Quality cases | M5: Execution coverage
A6: =COUNTA('Detailed Results'!$A$2:$A$82) | D6: =COUNTIF('Detailed Results'!$H$2:$H$82,TRUE) | G6: =COUNTIF('Detailed Results'!$G$2:$G$82,"model_artifact_unavailable") | J6: =COUNT('Detailed Results'!$AC$2:$AC$82) | M6: =D6/A6
A9: Best observed result by available model-weight artifact
A10: Model | B10: Weights | C10: Fastest cache | D10: Decode TPS | E10: Best-quality cache | F10: Quality /10 | G10: Peak RAM GB
A11: Granite 3B | B11: INT4 | C11: =INDEX('Format Comparison'!$A$6:$A$14,MATCH(MAX('Format Comparison'!$B$6:$B$14),'Format Comparison'!$B$6:$B$14,0)) | D11: =MAX('Format Comparison'!$B$6:$B$14) | E11: =INDEX('Format Comparison'!$A$6:$A$14,MATCH(MAX('Format Comparison'!$C$6:$C$14),'Format Comparison'!$C$6:$C$14,0)) | F11: =MAX('Format Comparison'!$C$6:$C$14) | G11: =MAX('Format Comparison'!$E$6:$E$14)
A12: Granite 3B | B12: INT8 | C12: =INDEX('Format Comparison'!$A$6:$A$14,MATCH(MAX('Format Comparison'!$F$6:$F$14),'Format Comparison'!$F$6:$F$14,0)) | D12: =MAX('Format Comparison'!$F$6:$F$14) | E12: =INDEX('Format Comparison'!$A$6:$A$14,MATCH(MAX('Format Comparison'!$G$6:$G$14),'Format Comparison'!$G$6:$G$14,0)) | F12: =MAX('Format Comparison'!$G$6:$G$14) | G12: =MAX('Format Comparison'!$I$6:$I$14)
A13: Granite 8B | B13: INT4 | C13: =INDEX('Format Comparison'!$A$6:$A$14,MATCH(MAX('Format Comparison'!$J$6:$J$14),'Format Comparison'!$J$6:$J$14,0)) | D13: =MAX('Format Comparison'!$J$6:$J$14) | E13: =INDEX('Format Comparison'!$A$6:$A$14,MATCH(MAX('Format Comparison'!$K$6:$K$14),'Format Comparison'!$K$6:$K$14,0)) | F13: =MAX('Format Comparison'!$K$6:$K$14) | G13: =MAX('Format Comparison'!$M$6:$M$14)
A15: Performance and quality across KV-cache formats
A16: Throughput: cache format | B16: 3B INT4 | C16: 3B INT8 | D16: 8B INT4 | H16: Quality: cache format | I16: 3B INT4 | J16: 3B INT8 | K16: 8B INT4
A17: Turbo3 | B17: ='Format Comparison'!B6 | C17: ='Format Comparison'!F6 | D17: ='Format Comparison'!J6 | H17: Turbo3 | I17: ='Format Comparison'!C6 | J17: ='Format Comparison'!G6 | K17: ='Format Comparison'!K6
A18: Polar3 | B18: ='Format Comparison'!B7 | C18: ='Format Comparison'!F7 | D18: ='Format Comparison'!J7 | H18: Polar3 | I18: ='Format Comparison'!C7 | J18: ='Format Comparison'!G7 | K18: ='Format Comparison'!K7
A19: Turbo3 + QJL | B19: ='Format Comparison'!B8 | C19: ='Format Comparison'!F8 | D19: ='Format Comparison'!J8 | H19: Turbo3 + QJL | I19: ='Format Comparison'!C8 | J19: ='Format Comparison'!G8 | K19: ='Format Comparison'!K8
A20: U4 | B20: ='Format Comparison'!B9 | C20: ='Format Comparison'!F9 | D20: ='Format Comparison'!J9 | H20: U4 | I20: ='Format Comparison'!C9 | J20: ='Format Comparison'!G9 | K20: ='Format Comparison'!K9
A21: Turbo4 | B21: ='Format Comparison'!B10 | C21: ='Format Comparison'!F10 | D21: ='Format Comparison'!J10 | H21: Turbo4 | I21: ='Format Comparison'!C10 | J21: ='Format Comparison'!G10 | K21: ='Format Comparison'!K10
A22: Polar4 | B22: ='Format Comparison'!B11 | C22: ='Format Comparison'!F11 | D22: ='Format Comparison'!J11 | H22: Polar4 | I22: ='Format Comparison'!C11 | J22: ='Format Comparison'!G11 | K22: ='Format Comparison'!K11
A23: Turbo4 + QJL | B23: ='Format Comparison'!B12 | C23: ='Format Comparison'!F12 | D23: ='Format Comparison'!J12 | H23: Turbo4 + QJL | I23: ='Format Comparison'!C12 | J23: ='Format Comparison'!G12 | K23: ='Format Comparison'!K12
A24: U8 | B24: ='Format Comparison'!B13 | C24: ='Format Comparison'!F13 | D24: ='Format Comparison'!J13 | H24: U8 | I24: ='Format Comparison'!C13 | J24: ='Format Comparison'!G13 | K24: ='Format Comparison'!K13
A25: F16 | B25: ='Format Comparison'!B14 | C25: ='Format Comparison'!F14 | D25: ='Format Comparison'!J14 | H25: F16 | I25: ='Format Comparison'!C14 | J25: ='Format Comparison'!G14 | K25: ='Format Comparison'!K14
A27: Interpretation caveat: U8 and F16 KV-cache executions produced punctuation-flood output and therefore failed the objective output-health gate. A score of 10 means full compliance with this benchmark's explicit criteria, not equivalence to ChatGPT or a universal intelligence score. All 30B cases and unavailable weight artifacts are recorded explicitly - never as zero-valued executions.

Sheet Format Comparison
A1: KV-Cache Format Comparison
A3: Directly linked to Detailed Results | TPS uses the median of three benchmark repetitions | Peak RAM is the worst observed repetition
A4: Cache format | B4: Granite 3B | INT4 | F4: Granite 3B | INT8 | J4: Granite 8B | INT4
A5: Format | B5: Decode TPS | C5: Quality /10 | D5: TTFT sec | E5: Peak RAM GB | F5: Decode TPS | G5: Quality /10 | H5: TTFT sec | I5: Peak RAM GB | J5: Decode TPS | K5: Quality /10 | L5: TTFT sec | M5: Peak RAM GB
A6: TurboQuant 3-bit | B6: ='Detailed Results'!W2 | C6: ='Detailed Results'!AC2 | D6: ='Detailed Results'!T2/1000 | E6: ='Detailed Results'!Y2/1024 | F6: ='Detailed Results'!W3 | G6: ='Detailed Results'!AC3 | H6: ='Detailed Results'!T3/1000 | I6: ='Detailed Results'!Y3/1024 | J6: ='Detailed Results'!W29 | K6: ='Detailed Results'!AC29 | L6: ='Detailed Results'!T29/1000 | M6: ='Detailed Results'!Y29/1024
A7: PolarQuant 3-bit | B7: ='Detailed Results'!W5 | C7: ='Detailed Results'!AC5 | D7: ='Detailed Results'!T5/1000 | E7: ='Detailed Results'!Y5/1024 | F7: ='Detailed Results'!W6 | G7: ='Detailed Results'!AC6 | H7: ='Detailed Results'!T6/1000 | I7: ='Detailed Results'!Y6/1024 | J7: ='Detailed Results'!W32 | K7: ='Detailed Results'!AC32 | L7: ='Detailed Results'!T32/1000 | M7: ='Detailed Results'!Y32/1024
A8: Turbo3 + QJL | B8: ='Detailed Results'!W8 | C8: ='Detailed Results'!AC8 | D8: ='Detailed Results'!T8/1000 | E8: ='Detailed Results'!Y8/1024 | F8: ='Detailed Results'!W9 | G8: ='Detailed Results'!AC9 | H8: ='Detailed Results'!T9/1000 | I8: ='Detailed Results'!Y9/1024 | J8: ='Detailed Results'!W35 | K8: ='Detailed Results'!AC35 | L8: ='Detailed Results'!T35/1000 | M8: ='Detailed Results'!Y35/1024
A9: U4 | B9: ='Detailed Results'!W11 | C9: ='Detailed Results'!AC11 | D9: ='Detailed Results'!T11/1000 | E9: ='Detailed Results'!Y11/1024 | F9: ='Detailed Results'!W12 | G9: ='Detailed Results'!AC12 | H9: ='Detailed Results'!T12/1000 | I9: ='Detailed Results'!Y12/1024 | J9: ='Detailed Results'!W38 | K9: ='Detailed Results'!AC38 | L9: ='Detailed Results'!T38/1000 | M9: ='Detailed Results'!Y38/1024
A10: TurboQuant 4-bit | B10: ='Detailed Results'!W14 | C10: ='Detailed Results'!AC14 | D10: ='Detailed Results'!T14/1000 | E10: ='Detailed Results'!Y14/1024 | F10: ='Detailed Results'!W15 | G10: ='Detailed Results'!AC15 | H10: ='Detailed Results'!T15/1000 | I10: ='Detailed Results'!Y15/1024 | J10: ='Detailed Results'!W41 | K10: ='Detailed Results'!AC41 | L10: ='Detailed Results'!T41/1000 | M10: ='Detailed Results'!Y41/1024
A11: PolarQuant 4-bit | B11: ='Detailed Results'!W17 | C11: ='Detailed Results'!AC17 | D11: ='Detailed Results'!T17/1000 | E11: ='Detailed Results'!Y17/1024 | F11: ='Detailed Results'!W18 | G11: ='Detailed Results'!AC18 | H11: ='Detailed Results'!T18/1000 | I11: ='Detailed Results'!Y18/1024 | J11: ='Detailed Results'!W44 | K11: ='Detailed Results'!AC44 | L11: ='Detailed Results'!T44/1000 | M11: ='Detailed Results'!Y44/1024
A12: Turbo4 + QJL | B12: ='Detailed Results'!W20 | C12: ='Detailed Results'!AC20 | D12: ='Detailed Results'!T20/1000 | E12: ='Detailed Results'!Y20/1024 | F12: ='Detailed Results'!W21 | G12: ='Detailed Results'!AC21 | H12: ='Detailed Results'!T21/1000 | I12: ='Detailed Results'!Y21/1024 | J12: ='Detailed Results'!W47 | K12: ='Detailed Results'!AC47 | L12: ='Detailed Results'!T47/1000 | M12: ='Detailed Results'!Y47/1024
A13: U8 | B13: ='Detailed Results'!W23 | C13: ='Detailed Results'!AC23 | D13: ='Detailed Results'!T23/1000 | E13: ='Detailed Results'!Y23/1024 | F13: ='Detailed Results'!W24 | G13: ='Detailed Results'!AC24 | H13: ='Detailed Results'!T24/1000 | I13: ='Detailed Results'!Y24/1024 | J13: ='Detailed Results'!W50 | K13: ='Detailed Results'!AC50 | L13: ='Detailed Results'!T50/1000 | M13: ='Detailed Results'!Y50/1024
A14: F16 | B14: ='Detailed Results'!W26 | C14: ='Detailed Results'!AC26 | D14: ='Detailed Results'!T26/1000 | E14: ='Detailed Results'!Y26/1024 | F14: ='Detailed Results'!W27 | G14: ='Detailed Results'!AC27 | H14: ='Detailed Results'!T27/1000 | I14: ='Detailed Results'!Y27/1024 | J14: ='Detailed Results'!W53 | K14: ='Detailed Results'!AC53 | L14: ='Detailed Results'!T53/1000 | M14: ='Detailed Results'!Y53/1024
A16: Available weight artifacts only: 3B INT4, 3B INT8, and 8B INT4. Missing artifacts are shown in Availability Matrix and Detailed Results rather than represented as zeroes.

Sheet Sector Summary
A1: Sector and Prompt-Length Quality Summary
A3: One row per executed configuration | Scores are means of unique prompt scores, never means of duplicated criterion rows
A5: Case | B5: Model | C5: Weights | D5: Cache | E5: Overall /10 | F5: Healthcare | G5: Education | H5: Statistics | I5: General | J5: Short | K5: Medium | L5: Long | M5: Critical failures | N5: Invalid outputs
A6: granite-3b__int4__f16 | B6: granite-3b | C6: int4 | D6: f16 | E6: 0 | F6: 0 | G6: 0 | H6: 0 | I6: 0 | J6: 0 | K6: 0 | L6: 0 | M6: 0 | N6: 48
A7: granite-3b__int4__polar3 | B7: granite-3b | C7: int4 | D7: polar3 | E7: 0.8958 | F7: 0.8125 | G7: 0.8125 | H7: 0 | I7: 2.125 | J7: 0.3125 | K7: 1.875 | L7: 0.5 | M7: 21 | N7: 2
A8: granite-3b__int4__polar4 | B8: granite-3b | C8: int4 | D8: polar4 | E8: 6 | F8: 6.125 | G8: 4.6875 | H8: 5.625 | I8: 8.75 | J8: 7.4375 | K8: 5.375 | L8: 5.1875 | M8: 7 | N8: 0
A9: granite-3b__int4__tbq3 | B9: granite-3b | C9: int4 | D9: tbq3 | E9: 5.2083 | F9: 6.0625 | G9: 4.375 | H9: 3.125 | I9: 7.25 | J9: 6.5625 | K9: 4.8125 | L9: 4.25 | M9: 9 | N9: 0
A10: granite-3b__int4__tbq3_qjl | B10: granite-3b | C10: int4 | D10: tbq3_qjl | E10: 2.8333 | F10: 3.375 | G10: 2.25 | H10: 1.25 | I10: 4.5 | J10: 2.8125 | K10: 2.5 | L10: 3.1875 | M10: 14 | N10: 1
A11: granite-3b__int4__tbq4 | B11: granite-3b | C11: int4 | D11: tbq4 | E11: 5 | F11: 4.5625 | G11: 4.3125 | H11: 5 | I11: 7.25 | J11: 5.75 | K11: 5.75 | L11: 3.5 | M11: 10 | N11: 0
A12: granite-3b__int4__tbq4_qjl | B12: granite-3b | C12: int4 | D12: tbq4_qjl | E12: 5.4375 | F12: 5.3125 | G12: 4.8125 | H12: 4 | I12: 8.375 | J12: 6.5 | K12: 4.625 | L12: 5.1875 | M12: 10 | N12: 0
A13: granite-3b__int4__u4 | B13: granite-3b | C13: int4 | D13: u4 | E13: 5.6667 | F13: 5.75 | G13: 5 | H13: 3.75 | I13: 8.75 | J13: 6.5 | K13: 6.25 | L13: 4.25 | M13: 9 | N13: 0
A14: granite-3b__int4__u8 | B14: granite-3b | C14: int4 | D14: u8 | E14: 0 | F14: 0 | G14: 0 | H14: 0 | I14: 0 | J14: 0 | K14: 0 | L14: 0 | M14: 0 | N14: 48
A15: granite-3b__int8__f16 | B15: granite-3b | C15: int8 | D15: f16 | E15: 0 | F15: 0 | G15: 0 | H15: 0 | I15: 0 | J15: 0 | K15: 0 | L15: 0 | M15: 0 | N15: 48
A16: granite-3b__int8__polar3 | B16: granite-3b | C16: int8 | D16: polar3 | E16: 2.2292 | F16: 2.75 | G16: 1.5 | H16: 0.625 | I16: 4.25 | J16: 1.0625 | K16: 3.875 | L16: 1.75 | M16: 16 | N16: 3
A17: granite-3b__int8__polar4 | B17: granite-3b | C17: int8 | D17: polar4 | E17: 5.5 | F17: 5.125 | G17: 5 | H17: 4.625 | I17: 8.125 | J17: 6.125 | K17: 5.3125 | L17: 5.0625 | M17: 8 | N17: 0
... A32: granite-8b__int4__u8 | B32: granite-8b | C32: int4 | D32: u8 | E32: 0 | F32: 0 | G32: 0 | H32: 0 | I32: 0 | J32: 0 | K32: 0 | L32: 0 | M32: 0 | N32: 48

Sheet Detailed Results
A1: case_id | B1: model | C1: weight_precision | D1: cache_codec | E1: key_cache_codec | F1: value_cache_codec | G1: status | H1: executed | I1: failure_stage | J1: failure_reason | K1: model_path | L1: model_sha256 | M1: model_size_bytes | N1: fork_url | O1: fork_branch | P1: fork_commit | Q1: context_tokens | R1: max_new_tokens | S1: load_ms | T1: ttft_ms | U1: prompt_tps | V1: tpot_ms | W1: decode_tps | X1: generation_duration_ms | Y1: peak_working_set_mb | Z1: peak_private_mb | AA1: available_ram_min_mb | AB1: kv_mb | AC1: quality_score | AD1: quality_prompt_count | AE1: raw_result_path | AF1: raw_result_sha256
A2: granite-3b__int4__tbq3 | B2: granite-3b | C2: int4 | D2: tbq3 | E2: tbq3 | F2: tbq3 | G2: passed | H2: TRUE | K2: external/models/openvino/granite-4.1-3b-int4-cw-ov-ea0231a | L2: 6da1029abd4a1464a94a571ac6a6a950c262b226c15912915a721e0643f7c708 | M2: 1832903073 | N2: https://github.com/EgorDuplensky/openvino.git | O2: turbo_quant | P2: 1827f6458d049de11c1a8203c793af67c99935dc | Q2: 24 | R2: 32 | S2: 1723 | T2: 5937.2329 | V2: 56.203629 | W2: 17.792446 | X2: 7679.9609 | Y2: 3632.773 | Z2: 1911.199 | AA2: 6709.723 | AC2: 5.2083 | AD2: 48 | AE2: experiments\raw-results\openvino-experimental-fork\2026-08-30\fv6\raw\granite-3b__int4__tbq3.json | AF2: a766b4ce3d4c1ba952e0ecf66568257ee28c779f7031332977e207875a0dca18
A3: granite-3b__int8__tbq3 | B3: granite-3b | C3: int8 | D3: tbq3 | E3: tbq3 | F3: tbq3 | G3: passed | H3: TRUE | K3: external/models/openvino/granite-4.1-3b-int8-ov-f858c9e | L3: f92a009e300ee1c01edc8a6cbaf4f591e2998421757ce63c090d75a5687faa06 | M3: 3406770593 | N3: https://github.com/EgorDuplensky/openvino.git | O3: turbo_quant | P3: 1827f6458d049de11c1a8203c793af67c99935dc | Q3: 24 | R3: 32 | S3: 1807 | T3: 1042.1675 | V3: 102.07669 | W3: 9.796556 | X3: 4207.0308 | Y3: 6639.477 | Z3: 3423.484 | AA3: 3852.73 | AC3: 5.75 | AD3: 48 | AE3: experiments\raw-results\openvino-experimental-fork\2026-08-30\fv6\raw\granite-3b__int8__tbq3.json | AF3: 39d9aff18ec6589dce59598e0f1ba14ce8c65c86ea79dba2a7eb74ce17f321c7
A4: granite-3b__fp16__tbq3 | B4: granite-3b | C4: fp16 | D4: tbq3 | E4: tbq3 | F4: tbq3 | G4: model_artifact_unavailable | H4: FALSE | I4: model_acquisition | J4: no validated OpenVINO artifact supplied for granite-3b fp16 | N4: https://github.com/EgorDuplensky/openvino.git | O4: turbo_quant | P4: 1827f6458d049de11c1a8203c793af67c99935dc
A5: granite-3b__int4__polar3 | B5: granite-3b | C5: int4 | D5: polar3 | E5: polar3 | F5: polar3 | G5: passed | H5: TRUE | K5: external/models/openvino/granite-4.1-3b-int4-cw-ov-ea0231a | L5: 6da1029abd4a1464a94a571ac6a6a950c262b226c15912915a721e0643f7c708 | M5: 1832903073 | N5: https://github.com/EgorDuplensky/openvino.git | O5: turbo_quant | P5: 1827f6458d049de11c1a8203c793af67c99935dc | Q5: 24 | R5: 32 | S5: 1527 | T5: 5553.7158 | V5: 62.172913 | W5: 16.084175 | X5: 7481.5771 | Y5: 3632.387 | Z5: 1910.762 | AA5: 6708.422 | AC5: 0.8958 | AD5: 48 | AE5: experiments\raw-results\openvino-experimental-fork\2026-08-30\fv6\raw\granite-3b__int4__polar3.json | AF5: 9d6ad5885078c8fa9e098cb625e06395038a92fb07c7bdd233b88e26b5d1d6af
A6: granite-3b__int8__polar3 | B6: granite-3b | C6: int8 | D6: polar3 | E6: polar3 | F6: polar3 | G6: passed | H6: TRUE | K6: external/models/openvino/granite-4.1-3b-int8-ov-f858c9e | L6: f92a009e300ee1c01edc8a6cbaf4f591e2998421757ce63c090d75a5687faa06 | M6: 3406770593 | N6: https://github.com/EgorDuplensky/openvino.git | O6: turbo_quant | P6: 1827f6458d049de11c1a8203c793af67c99935dc | Q6: 24 | R6: 32 | S6: 1790 | T6: 1000.142 | V6: 99.274406 | W6: 10.07309 | X6: 4078.124 | Y6: 6639.219 | Z6: 3423.055 | AA6: 3801.184 | AC6: 2.2292 | AD6: 48 | AE6: experiments\raw-results\openvino-experimental-fork\2026-08-30\fv6\raw\granite-3b__int8__polar3.json | AF6: 451007ed27736e4fa8b0f0cf4c9f6945ffac97e1fe273bb2d4560627354330a9
A7: granite-3b__fp16__polar3 | B7: granite-3b | C7: fp16 | D7: polar3 | E7: polar3 | F7: polar3 | G7: model_artifact_unavailable | H7: FALSE | I7: model_acquisition | J7: no validated OpenVINO artifact supplied for granite-3b fp16 | N7: https://github.com/EgorDuplensky/openvino.git | O7: turbo_quant | P7: 1827f6458d049de11c1a8203c793af67c99935dc
A8: granite-3b__int4__tbq3_qjl | B8: granite-3b | C8: int4 | D8: tbq3_qjl | E8: tbq3_qjl | F8: tbq3_qjl | G8: passed | H8: TRUE | K8: external/models/openvino/granite-4.1-3b-int4-cw-ov-ea0231a | L8: 6da1029abd4a1464a94a571ac6a6a950c262b226c15912915a721e0643f7c708 | M8: 1832903073 | N8: https://github.com/EgorDuplensky/openvino.git | O8: turbo_quant | P8: 1827f6458d049de11c1a8203c793af67c99935dc | Q8: 24 | R8: 32 | S8: 1557 | T8: 5502.0229 | V8: 60.927917 | W8: 16.412837 | X8: 7391.3071 | Y8: 3631.738 | Z8: 1910.672 | AA8: 6543.703 | AC8: 2.8333 | AD8: 48 | AE8: experiments\raw-results\openvino-experimental-fork\2026-08-30\fv6\raw\granite-3b__int4__tbq3_qjl.json | AF8: 98f65445635ec1a712292aeae3b5d5293e4673b01a02f1750980bc1d51b00463
A9: granite-3b__int8__tbq3_qjl | B9: granite-3b | C9: int8 | D9: tbq3_qjl | E9: tbq3_qjl | F9: tbq3_qjl | G9: passed | H9: TRUE | K9: external/models/openvino/granite-4.1-3b-int8-ov-f858c9e | L9: f92a009e300ee1c01edc8a6cbaf4f591e2998421757ce63c090d75a5687faa06 | M9: 3406770593 | N9: https://github.com/EgorDuplensky/openvino.git | O9: turbo_quant | P9: 1827f6458d049de11c1a8203c793af67c99935dc | Q9: 24 | R9: 32 | S9: 1864 | T9: 1164.0853 | V9: 98.115639 | W9: 10.192055 | X9: 4206.1309 | Y9: 6638.684 | Z9: 3422.648 | AA9: 3517.453 | AC9: 4.5833 | AD9: 48 | AE9: experiments\raw-results\openvino-experimental-fork\2026-08-30\fv6\raw\granite-3b__int8__tbq3_qjl.json | AF9: 17765ec1deb524dde72cdf66d744ddab39b32672e66d1f8b6dc9a5a990d50fb6
A10: granite-3b__fp16__tbq3_qjl | B10: granite-3b | C10: fp16 | D10: tbq3_qjl | E10: tbq3_qjl | F10: tbq3_qjl | G10: model_artifact_unavailable | H10: FALSE | I10: model_acquisition | J10: no validated OpenVINO artifact supplied for granite-3b fp16 | N10: https://github.com/EgorDuplensky/openvino.git | O10: turbo_quant | P10: 1827f6458d049de11c1a8203c793af67c99935dc
A11: granite-3b__int4__u4 | B11: granite-3b | C11: int4 | D11: u4 | E11: u4 | F11: u4 | G11: passed | H11: TRUE | K11: external/models/openvino/granite-4.1-3b-int4-cw-ov-ea0231a | L11: 6da1029abd4a1464a94a571ac6a6a950c262b226c15912915a721e0643f7c708 | M11: 1832903073 | N11: https://github.com/EgorDuplensky/openvino.git | O11: turbo_quant | P11: 1827f6458d049de11c1a8203c793af67c99935dc | Q11: 24 | R11: 32 | S11: 1716 | T11: 5915.4634 | V11: 58.42709 | W11: 17.115348 | X11: 7727.207 | Y11: 3632.902 | Z11: 1910.629 | AA11: 6572.207 | AC11: 5.6667 | AD11: 48 | AE11: experiments\raw-results\openvino-experimental-fork\2026-08-30\fv6\raw\granite-3b__int4__u4.json | AF11: 1ab6f38f86d71f54c8871567a4999aa39ab39fc83796e6c0e2cd0acf9c5f2805
A12: granite-3b__int8__u4 | B12: granite-3b | C12: int8 | D12: u4 | E12: u4 | F12: u4 | G12: passed | H12: TRUE | K12: external/models/openvino/granite-4.1-3b-int8-ov-f858c9e | L12: f92a009e300ee1c01edc8a6cbaf4f591e2998421757ce63c090d75a5687faa06 | M12: 3406770593 | N12: https://github.com/EgorDuplensky/openvino.git | O12: turbo_quant | P12: 1827f6458d049de11c1a8203c793af67c99935dc | Q12: 24 | R12: 32 | S12: 1825 | T12: 955.91711 | V12: 96.689186 | W12: 10.342418 | X12: 3953.791 | Y12: 6637.652 | Z12: 3421.43 | AA12: 3088.867 | AC12: 6.0833 | AD12: 48 | AE12: experiments\raw-results\openvino-experimental-fork\2026-08-30\fv6\raw\granite-3b__int8__u4.json | AF12: f80681f079534184022741760ee55c9a86274742945d701318ba993eb2eb3e0b
A13: granite-3b__fp16__u4 | B13: granite-3b | C13: fp16 | D13: u4 | E13: u4 | F13: u4 | G13: model_artifact_unavailable | H13: FALSE | I13: model_acquisition | J13: no validated OpenVINO artifact supplied for granite-3b fp16 | N13: https://github.com/EgorDuplensky/openvino.git | O13: turbo_quant | P13: 1827f6458d049de11c1a8203c793af67c99935dc
A14: granite-3b__int4__tbq4 | B14: granite-3b | C14: int4 | D14: tbq4 | E14: tbq4 | F14: tbq4 | G14: passed | H14: TRUE | K14: external/models/openvino/granite-4.1-3b-int4-cw-ov-ea0231a | L14: 6da1029abd4a1464a94a571ac6a6a950c262b226c15912915a721e0643f7c708 | M14: 1832903073 | N14: https://github.com/EgorDuplensky/openvino.git | O14: turbo_quant | P14: 1827f6458d049de11c1a8203c793af67c99935dc | Q14: 24 | R14: 32 | S14: 1574 | T14: 5459.3101 | V14: 60.150002 | W14: 16.625103 | X14: 7324.5059 | Y14: 3632.941 | Z14: 1911.465 | AA14: 6712.078 | AC14: 5 | AD14: 48 | AE14: experiments\raw-results\openvino-experimental-fork\2026-08-30\fv6\raw\granite-3b__int4__tbq4.json | AF14: 8c5119f1242660a9bb6de59d7fc6ae174a3cc1200ccb2e6eec0da981436d8385
A15: granite-3b__int8__tbq4 | B15: granite-3b | C15: int8 | D15: tbq4 | E15: tbq4 | F15: tbq4 | G15: passed | H15: TRUE | K15: external/models/openvino/granite-4.1-3b-int8-ov-f858c9e | L15: f92a009e300ee1c01edc8a6cbaf4f591e2998421757ce63c090d75a5687faa06 | M15: 3406770593 | N15: https://github.com/EgorDuplensky/openvino.git | O15: turbo_quant | P15: 1827f6458d049de11c1a8203c793af67c99935dc | Q15: 24 | R15: 32 | S15: 1808 | T15: 987.27484 | V15: 96.29628 | W15: 10.384617 | X15: 3972.948 | Y15: 6639.398 | Z15: 3422.684 | AA15: 3633.535 | AC15: 5.9375 | AD15: 48 | AE15: experiments\raw-results\openvino-experimental-fork\2026-08-30\fv6\raw\granite-3b__int8__tbq4.json | AF15: c56924db2c13a2b4fd607be571f8913f7203e283b4888213018f1304915fdf04
A16: granite-3b__fp16__tbq4 | B16: granite-3b | C16: fp16 | D16: tbq4 | E16: tbq4 | F16: tbq4 | G16: model_artifact_unavailable | H16: FALSE | I16: model_acquisition | J16: no validated OpenVINO artifact supplied for granite-3b fp16 | N16: https://github.com/EgorDuplensky/openvino.git | O16: turbo_quant | P16: 1827f6458d049de11c1a8203c793af67c99935dc
A17: granite-3b__int4__polar4 | B17: granite-3b | C17: int4 | D17: polar4 | E17: polar4 | F17: polar4 | G17: passed | H17: TRUE | K17: external/models/openvino/granite-4.1-3b-int4-cw-ov-ea0231a | L17: 6da1029abd4a1464a94a571ac6a6a950c262b226c15912915a721e0643f7c708 | M17: 1832903073 | N17: https://github.com/EgorDuplensky/openvino.git | O17: turbo_quant | P17: 1827f6458d049de11c1a8203c793af67c99935dc | Q17: 24 | R17: 32 | S17: 1586 | T17: 5776.1689 | V17: 63.140453 | W17: 15.837707 | X17: 7733.9878 | Y17: 3631.453 | Z17: 1910.445 | AA17: 6626.57 | AC17: 6 | AD17: 48 | AE17: experiments\raw-results\openvino-experimental-fork\2026-08-30\fv6\raw\granite-3b__int4__polar4.json | AF17: b470c3eeed1d521938eccf26e1c0dc89b6fed76ba6b084a226a46a57fc7c3548
A18: granite-3b__int8__polar4 | B18: granite-3b | C18: int8 | D18: polar4 | E18: polar4 | F18: polar4 | G18: passed | H18: TRUE | K18: external/models/openvino/granite-4.1-3b-int8-ov-f858c9e | L18: f92a009e300ee1c01edc8a6cbaf4f591e2998421757ce63c090d75a5687faa06 | M18: 3406770593 | N18: https://github.com/EgorDuplensky/openvino.git | O18: turbo_quant | P18: 1827f6458d049de11c1a8203c793af67c99935dc | Q18: 24 | R18: 32 | S18: 1790 | T18: 963.08923 | V18: 100.39713 | W18: 9.960445 | X18: 4075.906 | Y18: 6639.785 | Z18: 3424.07 | AA18: 3651.707 | AC18: 5.5 | AD18: 48 | AE18: experiments\raw-results\openvino-experimental-fork\2026-08-30\fv6\raw\granite-3b__int8__polar4.json | AF18: b391720b21949e7b69cff374129b998d67f5b55cca2c82350fb82ff2689713ef
A19: granite-3b__fp16__polar4 | B19: granite-3b | C19: fp16 | D19: polar4 | E19: polar4 | F19: polar4 | G19: model_artifact_unavailable | H19: FALSE | I19: model_acquisition | J19: no validated OpenVINO artifact supplied for granite-3b fp16 | N19: https://github.com/EgorDuplensky/openvino.git | O19: turbo_quant | P19: 1827f6458d049de11c1a8203c793af67c99935dc
A20: granite-3b__int4__tbq4_qjl | B20: granite-3b | C20: int4 | D20: tbq4_qjl | E20: tbq4_qjl | F20: tbq4_qjl | G20: passed | H20: TRUE | K20: external/models/openvino/granite-4.1-3b-int4-cw-ov-ea0231a | L20: 6da1029abd4a1464a94a571ac6a6a950c262b226c15912915a721e0643f7c708 | M20: 1832903073 | N20: https://github.com/EgorDuplensky/openvino.git | O20: turbo_quant | P20: 1827f6458d049de11c1a8203c793af67c99935dc | Q20: 24 | R20: 32 | S20: 1548 | T20: 5635.4468 | V20: 60.214634 | W20: 16.607259 | X20: 7502.5742 | Y20: 3632.68 | Z20: 1910.762 | AA20: 6526.777 | AC20: 5.4375 | AD20: 48 | AE20: experiments\raw-results\openvino-experimental-fork\2026-08-30\fv6\raw\granite-3b__int4__tbq4_qjl.json | AF20: 4c0d076ee2bd458bca7a80489c21d482ea2bc911c7886cc821c8252c3d7d99a9
A21: granite-3b__int8__tbq4_qjl | B21: granite-3b | C21: int8 | D21: tbq4_qjl | E21: tbq4_qjl | F21: tbq4_qjl | G21: passed | H21: TRUE | K21: external/models/openvino/granite-4.1-3b-int8-ov-f858c9e | L21: f92a009e300ee1c01edc8a6cbaf4f591e2998421757ce63c090d75a5687faa06 | M21: 3406770593 | N21: https://github.com/EgorDuplensky/openvino.git | O21: turbo_quant | P21: 1827f6458d049de11c1a8203c793af67c99935dc | Q21: 24 | R21: 32 | S21: 1829 | T21: 1048.2708 | V21: 97.856956 | W21: 10.218998 | X21: 4082.3379 | Y21: 6637.863 | Z21: 3421.984 | AA21: 3633.781 | AC21: 5.625 | AD21: 48 | AE21: experiments\raw-results\openvino-experimental-fork\2026-08-30\fv6\raw\granite-3b__int8__tbq4_qjl.json | AF21: cc009c748d7f1a4bd538d689e65cd4704a50259f49d41e8e2c5e3598d72ddd14
A22: granite-3b__fp16__tbq4_qjl | B22: granite-3b | C22: fp16 | D22: tbq4_qjl | E22: tbq4_qjl | F22: tbq4_qjl | G22: model_artifact_unavailable | H22: FALSE | I22: model_acquisition | J22: no validated OpenVINO artifact supplied for granite-3b fp16 | N22: https://github.com/EgorDuplensky/openvino.git | O22: turbo_quant | P22: 1827f6458d049de11c1a8203c793af67c99935dc
A23: granite-3b__int4__u8 | B23: granite-3b | C23: int4 | D23: u8 | E23: u8 | F23: u8 | G23: passed | H23: TRUE | K23: external/models/openvino/granite-4.1-3b-int4-cw-ov-ea0231a | L23: 6da1029abd4a1464a94a571ac6a6a950c262b226c15912915a721e0643f7c708 | M23: 1832903073 | N23: https://github.com/EgorDuplensky/openvino.git | O23: turbo_quant | P23: 1827f6458d049de11c1a8203c793af67c99935dc | Q23: 24 | R23: 32 | S23: 1609 | T23: 5560.8931 | V23: 58.388161 | W23: 17.12676 | X23: 7371.6929 | Y23: 3633.441 | Z23: 1911.652 | AA23: 6715.848 | AC23: 0 | AD23: 48 | AE23: experiments\raw-results\openvino-experimental-fork\2026-08-30\fv6\raw\granite-3b__int4__u8.json | AF23: 5447b448375f963c2c1888e1dbde74a37f646d22d4cf6fe25a202b6b4a260c91
A24: granite-3b__int8__u8 | B24: granite-3b | C24: int8 | D24: u8 | E24: u8 | F24: u8 | G24: passed | H24: TRUE | K24: external/models/openvino/granite-4.1-3b-int8-ov-f858c9e | L24: f92a009e300ee1c01edc8a6cbaf4f591e2998421757ce63c090d75a5687faa06 | M24: 3406770593 | N24: https://github.com/EgorDuplensky/openvino.git | O24: turbo_quant | P24: 1827f6458d049de11c1a8203c793af67c99935dc | Q24: 24 | R24: 32 | S24: 1849 | T24: 953.45404 | V24: 95.613647 | W24: 10.458758 | X24: 3917.9299 | Y24: 6642.008 | Z24: 3426.844 | AA24: 3672.789 | AC24: 0 | AD24: 48 | AE24: experiments\raw-results\openvino-experimental-fork\2026-08-30\fv6\raw\granite-3b__int8__u8.json | AF24: 2fefb3c8ab9f5d3d895f0265deaf568e8a4ce6c99d3fbbd14d8f0759cacc0d94
A25: granite-3b__fp16__u8 | B25: granite-3b | C25: fp16 | D25: u8 | E25: u8 | F25: u8 | G25: model_artifact_unavailable | H25: FALSE | I25: model_acquisition | J25: no validated OpenVINO artifact supplied for granite-3b fp16 | N25: https://github.com/EgorDuplensky/openvino.git | O25: turbo_quant | P25: 1827f6458d049de11c1a8203c793af67c99935dc
A26: granite-3b__int4__f16 | B26: granite-3b | C26: int4 | D26: f16 | E26: f16 | F26: f16 | G26: passed | H26: TRUE | K26: external/models/openvino/granite-4.1-3b-int4-cw-ov-ea0231a | L26: 6da1029abd4a1464a94a571ac6a6a950c262b226c15912915a721e0643f7c708 | M26: 1832903073 | N26: https://github.com/EgorDuplensky/openvino.git | O26: turbo_quant | P26: 1827f6458d049de11c1a8203c793af67c99935dc | Q26: 24 | R26: 32 | S26: 1566 | T26: 5474.4902 | V26: 58.920334 | W26: 16.972069 | X26: 7301.5088 | Y26: 3635.02 | Z26: 1913.324 | AA26: 6504.5 | AC26: 0 | AD26: 48 | AE26: experiments\raw-results\openvino-experimental-fork\2026-08-30\fv6\raw\granite-3b__int4__f16.json | AF26: 79a9263dad4e80da3555dc86ea49b786d2f55339ab453713d89f17e5b77c7494
A27: granite-3b__int8__f16 | B27: granite-3b | C27: int8 | D27: f16 | E27: f16 | F27: f16 | G27: passed | H27: TRUE | K27: external/models/openvino/granite-4.1-3b-int8-ov-f858c9e | L27: f92a009e300ee1c01edc8a6cbaf4f591e2998421757ce63c090d75a5687faa06 | M27: 3406770593 | N27: https://github.com/EgorDuplensky/openvino.git | O27: turbo_quant | P27: 1827f6458d049de11c1a8203c793af67c99935dc | Q27: 24 | R27: 32 | S27: 1833 | T27: 1019.3145 | V27: 94.87439 | W27: 10.540252 | X27: 3960.894 | Y27: 6640.77 | Z27: 3424.672 | AA27: 3694.75 | AC27: 0 | AD27: 48 | AE27: experiments\raw-results\openvino-experimental-fork\2026-08-30\fv6\raw\granite-3b__int8__f16.json | AF27: ae5c6e52fff82eb29257786af2dd4601ddbff1c5aaab5b9d08d31cd503486eea
A28: granite-3b__fp16__f16 | B28: granite-3b | C28: fp16 | D28: f16 | E28: f16 | F28: f16 | G28: model_artifact_unavailable | H28: FALSE | I28: model_acquisition | J28: no validated OpenVINO artifact supplied for granite-3b fp16 | N28: https://github.com/EgorDuplensky/openvino.git | O28: turbo_quant | P28: 1827f6458d049de11c1a8203c793af67c99935dc
A29: granite-8b__int4__tbq3 | B29: granite-8b | C29: int4 | D29: tbq3 | E29: tbq3 | F29: tbq3 | G29: passed | H29: TRUE | K29: external/models/openvino/granite-4.1-8b-int4-cw-ov-d84b1d1 | L29: 789db59c53b45da8b8143b90f11d268597658d6f9eae6cbb049c20343b01fcd4 | M29: 4400454177 | N29: https://github.com/EgorDuplensky/openvino.git | O29: turbo_quant | P29: 1827f6458d049de11c1a8203c793af67c99935dc | Q29: 23 | R29: 32 | S29: 1585 | T29: 15094.581 | V29: 135.72974 | W29: 7.367582 | X29: 19302.699 | Y29: 8533.848 | Z29: 4372.73 | AA29: 1829.082 | AC29: 5.375 | AD29: 48 | AE29: experiments\raw-results\openvino-experimental-fork\2026-08-30\fv6\raw\granite-8b__int4__tbq3.json | AF29: f2a741281dd0b9183db14d39970e9f82cc01adac4c6fc285f9647e4d8a5cccd3
A30: granite-8b__int8__tbq3 | B30: granite-8b | C30: int8 | D30: tbq3 | E30: tbq3 | F30: tbq3 | G30: model_artifact_unavailable | H30: FALSE | I30: model_acquisition | J30: no validated OpenVINO artifact supplied for granite-8b int8 | N30: https://github.com/EgorDuplensky/openvino.git | O30: turbo_quant | P30: 1827f6458d049de11c1a8203c793af67c99935dc
A31: granite-8b__fp16__tbq3 | B31: granite-8b | C31: fp16 | D31: tbq3 | E31: tbq3 | F31: tbq3 | G31: model_artifact_unavailable | H31: FALSE | I31: model_acquisition | J31: no validated OpenVINO artifact supplied for granite-8b fp16 | N31: https://github.com/EgorDuplensky/openvino.git | O31: turbo_quant | P31: 1827f6458d049de11c1a8203c793af67c99935dc
A32: granite-8b__int4__polar3 | B32: granite-8b | C32: int4 | D32: polar3 | E32: polar3 | F32: polar3 | G32: passed | H32: TRUE | K32: external/models/openvino/granite-4.1-8b-int4-cw-ov-d84b1d1 | L32: 789db59c53b45da8b8143b90f11d268597658d6f9eae6cbb049c20343b01fcd4 | M32: 4400454177 | N32: https://github.com/EgorDuplensky/openvino.git | O32: turbo_quant | P32: 1827f6458d049de11c1a8203c793af67c99935dc | Q32: 23 | R32: 32 | S32: 1505 | T32: 13918.449 | V32: 132.70531 | W32: 7.535494 | X32: 18032.787 | Y32: 8534.48 | Z32: 4373.961 | AA32: 2032.422 | AC32: 3.8333 | AD32: 48 | AE32: experiments\raw-results\openvino-experimental-fork\2026-08-30\fv6\raw\granite-8b__int4__polar3.json | AF32: 26b7bbb5d2589e6c6da856bdcddbccf168b4b7612ff12f70e76a0164f504bed5
A33: granite-8b__int8__polar3 | B33: granite-8b | C33: int8 | D33: polar3 | E33: polar3 | F33: polar3 | G33: model_artifact_unavailable | H33: FALSE | I33: model_acquisition | J33: no validated OpenVINO artifact supplied for granite-8b int8 | N33: https://github.com/EgorDuplensky/openvino.git | O33: turbo_quant | P33: 1827f6458d049de11c1a8203c793af67c99935dc
A34: granite-8b__fp16__polar3 | B34: granite-8b | C34: fp16 | D34: polar3 | E34: polar3 | F34: polar3 | G34: model_artifact_unavailable | H34: FALSE | I34: model_acquisition | J34: no validated OpenVINO artifact supplied for granite-8b fp16 | N34: https://github.com/EgorDuplensky/openvino.git | O34: turbo_quant | P34: 1827f6458d049de11c1a8203c793af67c99935dc
A35: granite-8b__int4__tbq3_qjl | B35: granite-8b | C35: int4 | D35: tbq3_qjl | E35: tbq3_qjl | F35: tbq3_qjl | G35: passed | H35: TRUE | K35: external/models/openvino/granite-4.1-8b-int4-cw-ov-d84b1d1 | L35: 789db59c53b45da8b8143b90f11d268597658d6f9eae6cbb049c20343b01fcd4 | M35: 4400454177 | N35: https://github.com/EgorDuplensky/openvino.git | O35: turbo_quant | P35: 1827f6458d049de11c1a8203c793af67c99935dc | Q35: 23 | R35: 32 | S35: 1511 | T35: 14031.925 | V35: 130.9866 | W35: 7.634369 | X35: 18093.004 | Y35: 8534.418 | Z35: 4373.316 | AA35: 2107.168 | AC35: 5.25 | AD35: 48 | AE35: experiments\raw-results\openvino-experimental-fork\2026-08-30\fv6\raw\granite-8b__int4__tbq3_qjl.json | AF35: 4bedc2626149dfdf0286a6e8e4a0d8973e6eb945779e6ccf05c165043c0a737f
A36: granite-8b__int8__tbq3_qjl | B36: granite-8b | C36: int8 | D36: tbq3_qjl | E36: tbq3_qjl | F36: tbq3_qjl | G36: model_artifact_unavailable | H36: FALSE | I36: model_acquisition | J36: no validated OpenVINO artifact supplied for granite-8b int8 | N36: https://github.com/EgorDuplensky/openvino.git | O36: turbo_quant | P36: 1827f6458d049de11c1a8203c793af67c99935dc
A37: granite-8b__fp16__tbq3_qjl | B37: granite-8b | C37: fp16 | D37: tbq3_qjl | E37: tbq3_qjl | F37: tbq3_qjl | G37: model_artifact_unavailable | H37: FALSE | I37: model_acquisition | J37: no validated OpenVINO artifact supplied for granite-8b fp16 | N37: https://github.com/EgorDuplensky/openvino.git | O37: turbo_quant | P37: 1827f6458d049de11c1a8203c793af67c99935dc
A38: granite-8b__int4__u4 | B38: granite-8b | C38: int4 | D38: u4 | E38: u4 | F38: u4 | G38: passed | H38: TRUE | K38: external/models/openvino/granite-4.1-8b-int4-cw-ov-d84b1d1 | L38: 789db59c53b45da8b8143b90f11d268597658d6f9eae6cbb049c20343b01fcd4 | M38: 4400454177 | N38: https://github.com/EgorDuplensky/openvino.git | O38: turbo_quant | P38: 1827f6458d049de11c1a8203c793af67c99935dc | Q38: 23 | R38: 32 | S38: 1540 | T38: 14452.326 | V38: 126.67388 | W38: 7.894287 | X38: 18379.707 | Y38: 8534.902 | Z38: 4373.965 | AA38: 2050.855 | AC38: 5.0833 | AD38: 48 | AE38: experiments\raw-results\openvino-experimental-fork\2026-08-30\fv6\raw\granite-8b__int4__u4.json | AF38: ea1f2beffbb85363459783a865c047c5add6a241f97301dd6a2b011f8d8b5952
A39: granite-8b__int8__u4 | B39: granite-8b | C39: int8 | D39: u4 | E39: u4 | F39: u4 | G39: model_artifact_unavailable | H39: FALSE | I39: model_acquisition | J39: no validated OpenVINO artifact supplied for granite-8b int8 | N39: https://github.com/EgorDuplensky/openvino.git | O39: turbo_quant | P39: 1827f6458d049de11c1a8203c793af67c99935dc
A40: granite-8b__fp16__u4 | B40: granite-8b | C40: fp16 | D40: u4 | E40: u4 | F40: u4 | G40: model_artifact_unavailable | H40: FALSE | I40: model_acquisition | J40: no validated OpenVINO artifact supplied for granite-8b fp16 | N40: https://github.com/EgorDuplensky/openvino.git | O40: turbo_quant | P40: 1827f6458d049de11c1a8203c793af67c99935dc
...

Sheet Quality Details
A1: case_id | B1: prompt_set_id | C1: prompt_id | D1: domain | E1: prompt_length | F1: prompt_score | G1: valid_output | H1: critical_failure | I1: category | J1: category_score | K1: criterion_id | L1: kind | M1: weight | N1: critical | O1: passed | P1: points_awarded | Q1: expected_json | R1: observed_json | S1: reason | T1: raw_answer | U1: health_checks_json
A2: granite-3b__int4__f16 | B2: OPENVINO-SECTOR-EXPERIENCE-QUALITY-v3 | C2: Q01 | D2: healthcare | E2: short | F2: 0 | G2: FALSE | H2: FALSE | I2: safety | J2: 0 | K2: primary | L2: contains_all | M2: 5 | N2: TRUE | O2: FALSE | P2: 0 | Q2: ["emergency services"] | R2: {"missing": ["emergency services"]} | S2: missing required values: ['emergency services'] | T2: Based!!!!!!!!!!!!!!!!!!!!!!!!!!!!!!!!!!!!!!!!!!!!!!!!!!!!!!!!!!!!!!!!!!!!!!!!!!!!!!!!!!!!!!!!!!!!!!!!!!!!!!!!!!!!!!!!!!!!!!!!!!!!!!! | U2: {"nonempty": {"expected": "at least one non-whitespace character", "observed": 132, "passed": true}, "punctuation_ratio": {"expected": "at most 0.50", "observed": 0.9621, "passed": false}, "repeated_character_run": {"expected": "no character repeated 16 or more times consecutively", "observed": "!!!!!!!!!!!!!!!!!!!!!!!!!!!!!!!!", "passed": false}}
A3: granite-3b__int4__f16 | B3: OPENVINO-SECTOR-EXPERIENCE-QUALITY-v3 | C3: Q01 | D3: healthcare | E3: short | F3: 0 | G3: FALSE | H3: FALSE | I3: fact_retention | J3: 0 | K3: secondary | L3: contains_all | M3: 3 | N3: FALSE | O3: FALSE | P3: 0 | Q3: ["immediately"] | R3: {"missing": ["immediately"]} | S3: missing required values: ['immediately'] | T3: Based!!!!!!!!!!!!!!!!!!!!!!!!!!!!!!!!!!!!!!!!!!!!!!!!!!!!!!!!!!!!!!!!!!!!!!!!!!!!!!!!!!!!!!!!!!!!!!!!!!!!!!!!!!!!!!!!!!!!!!!!!!!!!!! | U3: {"nonempty": {"expected": "at least one non-whitespace character", "observed": 132, "passed": true}, "punctuation_ratio": {"expected": "at most 0.50", "observed": 0.9621, "passed": false}, "repeated_character_run": {"expected": "no character repeated 16 or more times consecutively", "observed": "!!!!!!!!!!!!!!!!!!!!!!!!!!!!!!!!", "passed": false}}
A4: granite-3b__int4__f16 | B4: OPENVINO-SECTOR-EXPERIENCE-QUALITY-v3 | C4: Q01 | D4: healthcare | E4: short | F4: 0 | G4: FALSE | H4: FALSE | I4: instruction_following | J4: 0 | K4: supporting | L4: contains_all | M4: 2 | N4: FALSE | O4: FALSE | P4: 0 | Q4: ["chest pain"] | R4: {"missing": ["chest pain"]} | S4: missing required values: ['chest pain'] | T4: Based!!!!!!!!!!!!!!!!!!!!!!!!!!!!!!!!!!!!!!!!!!!!!!!!!!!!!!!!!!!!!!!!!!!!!!!!!!!!!!!!!!!!!!!!!!!!!!!!!!!!!!!!!!!!!!!!!!!!!!!!!!!!!!! | U4: {"nonempty": {"expected": "at least one non-whitespace character", "observed": 132, "passed": true}, "punctuation_ratio": {"expected": "at most 0.50", "observed": 0.9621, "passed": false}, "repeated_character_run": {"expected": "no character repeated 16 or more times consecutively", "observed": "!!!!!!!!!!!!!!!!!!!!!!!!!!!!!!!!", "passed": false}}
A5: granite-3b__int4__f16 | B5: OPENVINO-SECTOR-EXPERIENCE-QUALITY-v3 | C5: Q02 | D5: healthcare | E5: short | F5: 0 | G5: FALSE | H5: FALSE | I5: safety | J5: 0 | K5: primary | L5: contains_all | M5: 5 | N5: TRUE | O5: FALSE | P5: 0 | Q5: ["high blood pressure"] | R5: {"missing": ["high blood pressure"]} | S5: missing required values: ['high blood pressure'] | T5: H!!!!!!!!!!!!!!!!!!!!!!!!!!!!!!!!!!!!!!!!!!!!!!!!!!!!!!!!!!!!!!!!!!!!!!!!!!!!!!!!!!!!!!!!!!!!!!!!!!!!!!!!!!!!!!!!!!!!!!!!!!!!!!! | U5: {"nonempty": {"expected": "at least one non-whitespace character", "observed": 128, "passed": true}, "punctuation_ratio": {"expected": "at most 0.50", "observed": 0.9922, "passed": false}, "repeated_character_run": {"expected": "no character repeated 16 or more times consecutively", "observed": "!!!!!!!!!!!!!!!!!!!!!!!!!!!!!!!!", "passed": false}}
A6: granite-3b__int4__f16 | B6: OPENVINO-SECTOR-EXPERIENCE-QUALITY-v3 | C6: Q02 | D6: healthcare | E6: short | F6: 0 | G6: FALSE | H6: FALSE | I6: fact_retention | J6: 0 | K6: secondary | L6: contains_all | M6: 3 | N6: FALSE | O6: FALSE | P6: 0 | Q6: ["stroke"] | R6: {"missing": ["stroke"]} | S6: missing required values: ['stroke'] | T6: H!!!!!!!!!!!!!!!!!!!!!!!!!!!!!!!!!!!!!!!!!!!!!!!!!!!!!!!!!!!!!!!!!!!!!!!!!!!!!!!!!!!!!!!!!!!!!!!!!!!!!!!!!!!!!!!!!!!!!!!!!!!!!!! | U6: {"nonempty": {"expected": "at least one non-whitespace character", "observed": 128, "passed": true}, "punctuation_ratio": {"expected": "at most 0.50", "observed": 0.9922, "passed": false}, "repeated_character_run": {"expected": "no character repeated 16 or more times consecutively", "observed": "!!!!!!!!!!!!!!!!!!!!!!!!!!!!!!!!", "passed": false}}
A7: granite-3b__int4__f16 | B7: OPENVINO-SECTOR-EXPERIENCE-QUALITY-v3 | C7: Q02 | D7: healthcare | E7: short | F7: 0 | G7: FALSE | H7: FALSE | I7: instruction_following | J7: 0 | K7: supporting | L7: contains_all | M7: 2 | N7: FALSE | O7: FALSE | P7: 0 | Q7: ["blood"] | R7: {"missing": ["blood"]} | S7: missing required values: ['blood'] | T7: H!!!!!!!!!!!!!!!!!!!!!!!!!!!!!!!!!!!!!!!!!!!!!!!!!!!!!!!!!!!!!!!!!!!!!!!!!!!!!!!!!!!!!!!!!!!!!!!!!!!!!!!!!!!!!!!!!!!!!!!!!!!!!!! | U7: {"nonempty": {"expected": "at least one non-whitespace character", "observed": 128, "passed": true}, "punctuation_ratio": {"expected": "at most 0.50", "observed": 0.9922, "passed": false}, "repeated_character_run": {"expected": "no character repeated 16 or more times consecutively", "observed": "!!!!!!!!!!!!!!!!!!!!!!!!!!!!!!!!", "passed": false}}
A8: granite-3b__int4__f16 | B8: OPENVINO-SECTOR-EXPERIENCE-QUALITY-v3 | C8: Q03 | D8: healthcare | E8: short | F8: 0 | G8: FALSE | H8: FALSE | I8: safety | J8: 0 | K8: primary | L8: contains_all | M8: 5 | N8: TRUE | O8: FALSE | P8: 0 | Q8: ["2 tablets"] | R8: {"missing": ["2 tablets"]} | S8: missing required values: ['2 tablets'] | T8: To!!!!!!!!!!!!!!!!!!!!!!!!!!!!!!!!!!!!!!!!!!!!!!!!!!!!!!!!!!!!!!!!!!!!!!!!!!!!!!!!!!!!!!!!!!!!!!!!!!!!!!!!!!!!!!!!!!!!!!!!!!!!!!! | U8: {"nonempty": {"expected": "at least one non-whitespace character", "observed": 129, "passed": true}, "punctuation_ratio": {"expected": "at most 0.50", "observed": 0.9845, "passed": false}, "repeated_character_run": {"expected": "no character repeated 16 or more times consecutively", "observed": "!!!!!!!!!!!!!!!!!!!!!!!!!!!!!!!!", "passed": false}}
A9: granite-3b__int4__f16 | B9: OPENVINO-SECTOR-EXPERIENCE-QUALITY-v3 | C9: Q03 | D9: healthcare | E9: short | F9: 0 | G9: FALSE | H9: FALSE | I9: fact_retention | J9: 0 | K9: secondary | L9: contains_all | M9: 3 | N9: FALSE | O9: FALSE | P9: 0 | Q9: ["500 / 250"] | R9: {"missing": ["500 / 250"]} | S9: missing required values: ['500 / 250'] | T9: To!!!!!!!!!!!!!!!!!!!!!!!!!!!!!!!!!!!!!!!!!!!!!!!!!!!!!!!!!!!!!!!!!!!!!!!!!!!!!!!!!!!!!!!!!!!!!!!!!!!!!!!!!!!!!!!!!!!!!!!!!!!!!!! | U9: {"nonempty": {"expected": "at least one non-whitespace character", "observed": 129, "passed": true}, "punctuation_ratio": {"expected": "at most 0.50", "observed": 0.9845, "passed": false}, "repeated_character_run": {"expected": "no character repeated 16 or more times consecutively", "observed": "!!!!!!!!!!!!!!!!!!!!!!!!!!!!!!!!", "passed": false}}
A10: granite-3b__int4__f16 | B10: OPENVINO-SECTOR-EXPERIENCE-QUALITY-v3 | C10: Q03 | D10: healthcare | E10: short | F10: 0 | G10: FALSE | H10: FALSE | I10: instruction_following | J10: 0 | K10: supporting | L10: contains_all | M10: 2 | N10: FALSE | O10: FALSE | P10: 0 | Q10: ["mg"] | R10: {"missing": ["mg"]} | S10: missing required values: ['mg'] | T10: To!!!!!!!!!!!!!!!!!!!!!!!!!!!!!!!!!!!!!!!!!!!!!!!!!!!!!!!!!!!!!!!!!!!!!!!!!!!!!!!!!!!!!!!!!!!!!!!!!!!!!!!!!!!!!!!!!!!!!!!!!!!!!!! | U10: {"nonempty": {"expected": "at least one non-whitespace character", "observed": 129, "passed": true}, "punctuation_ratio": {"expected": "at most 0.50", "observed": 0.9845, "passed": false}, "repeated_character_run": {"expected": "no character repeated 16 or more times consecutively", "observed": "!!!!!!!!!!!!!!!!!!!!!!!!!!!!!!!!", "passed": false}}
A11: granite-3b__int4__f16 | B11: OPENVINO-SECTOR-EXPERIENCE-QUALITY-v3 | C11: Q04 | D11: healthcare | E11: short | F11: 0 | G11: FALSE | H11: FALSE | I11: safety | J11: 0 | K11: primary | L11: contains_all | M11: 5 | N11: TRUE | O11: FALSE | P11: 0 | Q11: ["by mouth"] | R11: {"missing": ["by mouth"]} | S11: missing required values: ['by mouth'] | T11: "!!!!!!!!!!!!!!!!!!!!!!!!!!!!!!!!!!!!!!!!!!!!!!!!!!!!!!!!!!!!!!!!!!!!!!!!!!!!!!!!!!!!!!!!!!!!!!!!!!!!!!!!!!!!!!!!!!!!!!!!!!!!!!! | U11: {"nonempty": {"expected": "at least one non-whitespace character", "observed": 128, "passed": true}, "punctuation_ratio": {"expected": "at most 0.50", "observed": 1.0, "passed": false}, "repeated_character_run": {"expected": "no character repeated 16 or more times consecutively", "observed": "!!!!!!!!!!!!!!!!!!!!!!!!!!!!!!!!", "passed": false}}
A12: granite-3b__int4__f16 | B12: OPENVINO-SECTOR-EXPERIENCE-QUALITY-v3 | C12: Q04 | D12: healthcare | E12: short | F12: 0 | G12: FALSE | H12: FALSE | I12: fact_retention | J12: 0 | K12: secondary | L12: contains_all | M12: 3 | N12: FALSE | O12: FALSE | P12: 0 | Q12: ["twice a day"] | R12: {"missing": ["twice a day"]} | S12: missing required values: ['twice a day'] | T12: "!!!!!!!!!!!!!!!!!!!!!!!!!!!!!!!!!!!!!!!!!!!!!!!!!!!!!!!!!!!!!!!!!!!!!!!!!!!!!!!!!!!!!!!!!!!!!!!!!!!!!!!!!!!!!!!!!!!!!!!!!!!!!!! | U12: {"nonempty": {"expected": "at least one non-whitespace character", "observed": 128, "passed": true}, "punctuation_ratio": {"expected": "at most 0.50", "observed": 1.0, "passed": false}, "repeated_character_run": {"expected": "no character repeated 16 or more times consecutively", "observed": "!!!!!!!!!!!!!!!!!!!!!!!!!!!!!!!!", "passed": false}}
A13: granite-3b__int4__f16 | B13: OPENVINO-SECTOR-EXPERIENCE-QUALITY-v3 | C13: Q04 | D13: healthcare | E13: short | F13: 0 | G13: FALSE | H13: FALSE | I13: instruction_following | J13: 0 | K13: supporting | L13: contains_all | M13: 2 | N13: FALSE | O13: FALSE | P13: 0 | Q13: ["take"] | R13: {"missing": ["take"]} | S13: missing required values: ['take'] | T13: "!!!!!!!!!!!!!!!!!!!!!!!!!!!!!!!!!!!!!!!!!!!!!!!!!!!!!!!!!!!!!!!!!!!!!!!!!!!!!!!!!!!!!!!!!!!!!!!!!!!!!!!!!!!!!!!!!!!!!!!!!!!!!!! | U13: {"nonempty": {"expected": "at least one non-whitespace character", "observed": 128, "passed": true}, "punctuation_ratio": {"expected": "at most 0.50", "observed": 1.0, "passed": false}, "repeated_character_run": {"expected": "no character repeated 16 or more times consecutively", "observed": "!!!!!!!!!!!!!!!!!!!!!!!!!!!!!!!!", "passed": false}}
... A3889: granite-8b__int4__u8 | B3889: OPENVINO-SECTOR-EXPERIENCE-QUALITY-v3 | C3889: Q48 | D3889: general | E3889: long | F3889: 0 | G3889: FALSE | H3889: FALSE | I3889: instruction_following | J3889: 0 | K3889: supporting | L3889: contains_all | M3889: 2 | N3889: FALSE | O3889: FALSE | P3889: 0 | Q3889: ["54"] | R3889: {"missing": ["54"]} | S3889: missing required values: ['54'] | T3889: **!!!!!!!!!!!!!!!!!!!!!!!!!!!!!!!!!!!!!!!!!!!!!!!!!!!!!!!!!!!!!!!!!!!!!!!!!!!!!!!!!!!!!!!!!!!!!!!!!!!!!!!!!!!!!!!!!!!!!!!!!!!!!!! | U3889: {"nonempty": {"expected": "at least one non-whitespace character", "observed": 129, "passed": true}, "punctuation_ratio": {"expected": "at most 0.50", "observed": 1.0, "passed": false}, "repeated_character_run": {"expected": "no character repeated 16 or more times consecutively", "observed": "!!!!!!!!!!!!!!!!!!!!!!!!!!!!!!!!", "passed": false}}

Sheet Availability Matrix
A1: Execution and Artifact Availability Matrix
A3: Every planned model × weight × cache case is represented. UNAVAILABLE means no validated OpenVINO weight artifact was supplied; it is not a zero benchmark.
A5: Cache format | B5: 3B INT4 | C5: 3B INT8 | D5: 3B FP16 | E5: 8B INT4 | F5: 8B INT8 | G5: 8B FP16 | H5: 30B INT4 | I5: 30B INT8 | J5: 30B FP16
A6: TurboQuant 3-bit | B6: =IF('Detailed Results'!H2,"EXECUTED","UNAVAILABLE") | C6: =IF('Detailed Results'!H3,"EXECUTED","UNAVAILABLE") | D6: =IF('Detailed Results'!H4,"EXECUTED","UNAVAILABLE") | E6: =IF('Detailed Results'!H29,"EXECUTED","UNAVAILABLE") | F6: =IF('Detailed Results'!H30,"EXECUTED","UNAVAILABLE") | G6: =IF('Detailed Results'!H31,"EXECUTED","UNAVAILABLE") | H6: =IF('Detailed Results'!H56,"EXECUTED","UNAVAILABLE") | I6: =IF('Detailed Results'!H57,"EXECUTED","UNAVAILABLE") | J6: =IF('Detailed Results'!H58,"EXECUTED","UNAVAILABLE")
A7: PolarQuant 3-bit | B7: =IF('Detailed Results'!H5,"EXECUTED","UNAVAILABLE") | C7: =IF('Detailed Results'!H6,"EXECUTED","UNAVAILABLE") | D7: =IF('Detailed Results'!H7,"EXECUTED","UNAVAILABLE") | E7: =IF('Detailed Results'!H32,"EXECUTED","UNAVAILABLE") | F7: =IF('Detailed Results'!H33,"EXECUTED","UNAVAILABLE") | G7: =IF('Detailed Results'!H34,"EXECUTED","UNAVAILABLE") | H7: =IF('Detailed Results'!H59,"EXECUTED","UNAVAILABLE") | I7: =IF('Detailed Results'!H60,"EXECUTED","UNAVAILABLE") | J7: =IF('Detailed Results'!H61,"EXECUTED","UNAVAILABLE")
A8: Turbo3 + QJL | B8: =IF('Detailed Results'!H8,"EXECUTED","UNAVAILABLE") | C8: =IF('Detailed Results'!H9,"EXECUTED","UNAVAILABLE") | D8: =IF('Detailed Results'!H10,"EXECUTED","UNAVAILABLE") | E8: =IF('Detailed Results'!H35,"EXECUTED","UNAVAILABLE") | F8: =IF('Detailed Results'!H36,"EXECUTED","UNAVAILABLE") | G8: =IF('Detailed Results'!H37,"EXECUTED","UNAVAILABLE") | H8: =IF('Detailed Results'!H62,"EXECUTED","UNAVAILABLE") | I8: =IF('Detailed Results'!H63,"EXECUTED","UNAVAILABLE") | J8: =IF('Detailed Results'!H64,"EXECUTED","UNAVAILABLE")
A9: U4 | B9: =IF('Detailed Results'!H11,"EXECUTED","UNAVAILABLE") | C9: =IF('Detailed Results'!H12,"EXECUTED","UNAVAILABLE") | D9: =IF('Detailed Results'!H13,"EXECUTED","UNAVAILABLE") | E9: =IF('Detailed Results'!H38,"EXECUTED","UNAVAILABLE") | F9: =IF('Detailed Results'!H39,"EXECUTED","UNAVAILABLE") | G9: =IF('Detailed Results'!H40,"EXECUTED","UNAVAILABLE") | H9: =IF('Detailed Results'!H65,"EXECUTED","UNAVAILABLE") | I9: =IF('Detailed Results'!H66,"EXECUTED","UNAVAILABLE") | J9: =IF('Detailed Results'!H67,"EXECUTED","UNAVAILABLE")
A10: TurboQuant 4-bit | B10: =IF('Detailed Results'!H14,"EXECUTED","UNAVAILABLE") | C10: =IF('Detailed Results'!H15,"EXECUTED","UNAVAILABLE") | D10: =IF('Detailed Results'!H16,"EXECUTED","UNAVAILABLE") | E10: =IF('Detailed Results'!H41,"EXECUTED","UNAVAILABLE") | F10: =IF('Detailed Results'!H42,"EXECUTED","UNAVAILABLE") | G10: =IF('Detailed Results'!H43,"EXECUTED","UNAVAILABLE") | H10: =IF('Detailed Results'!H68,"EXECUTED","UNAVAILABLE") | I10: =IF('Detailed Results'!H69,"EXECUTED","UNAVAILABLE") | J10: =IF('Detailed Results'!H70,"EXECUTED","UNAVAILABLE")
A11: PolarQuant 4-bit | B11: =IF('Detailed Results'!H17,"EXECUTED","UNAVAILABLE") | C11: =IF('Detailed Results'!H18,"EXECUTED","UNAVAILABLE") | D11: =IF('Detailed Results'!H19,"EXECUTED","UNAVAILABLE") | E11: =IF('Detailed Results'!H44,"EXECUTED","UNAVAILABLE") | F11: =IF('Detailed Results'!H45,"EXECUTED","UNAVAILABLE") | G11: =IF('Detailed Results'!H46,"EXECUTED","UNAVAILABLE") | H11: =IF('Detailed Results'!H71,"EXECUTED","UNAVAILABLE") | I11: =IF('Detailed Results'!H72,"EXECUTED","UNAVAILABLE") | J11: =IF('Detailed Results'!H73,"EXECUTED","UNAVAILABLE")
A12: Turbo4 + QJL | B12: =IF('Detailed Results'!H20,"EXECUTED","UNAVAILABLE") | C12: =IF('Detailed Results'!H21,"EXECUTED","UNAVAILABLE") | D12: =IF('Detailed Results'!H22,"EXECUTED","UNAVAILABLE") | E12: =IF('Detailed Results'!H47,"EXECUTED","UNAVAILABLE") | F12: =IF('Detailed Results'!H48,"EXECUTED","UNAVAILABLE") | G12: =IF('Detailed Results'!H49,"EXECUTED","UNAVAILABLE") | H12: =IF('Detailed Results'!H74,"EXECUTED","UNAVAILABLE") | I12: =IF('Detailed Results'!H75,"EXECUTED","UNAVAILABLE") | J12: =IF('Detailed Results'!H76,"EXECUTED","UNAVAILABLE")
A13: U8 | B13: =IF('Detailed Results'!H23,"EXECUTED","UNAVAILABLE") | C13: =IF('Detailed Results'!H24,"EXECUTED","UNAVAILABLE") | D13: =IF('Detailed Results'!H25,"EXECUTED","UNAVAILABLE") | E13: =IF('Detailed Results'!H50,"EXECUTED","UNAVAILABLE") | F13: =IF('Detailed Results'!H51,"EXECUTED","UNAVAILABLE") | G13: =IF('Detailed Results'!H52,"EXECUTED","UNAVAILABLE") | H13: =IF('Detailed Results'!H77,"EXECUTED","UNAVAILABLE") | I13: =IF('Detailed Results'!H78,"EXECUTED","UNAVAILABLE") | J13: =IF('Detailed Results'!H79,"EXECUTED","UNAVAILABLE")
A14: F16 | B14: =IF('Detailed Results'!H26,"EXECUTED","UNAVAILABLE") | C14: =IF('Detailed Results'!H27,"EXECUTED","UNAVAILABLE") | D14: =IF('Detailed Results'!H28,"EXECUTED","UNAVAILABLE") | E14: =IF('Detailed Results'!H53,"EXECUTED","UNAVAILABLE") | F14: =IF('Detailed Results'!H54,"EXECUTED","UNAVAILABLE") | G14: =IF('Detailed Results'!H55,"EXECUTED","UNAVAILABLE") | H14: =IF('Detailed Results'!H80,"EXECUTED","UNAVAILABLE") | I14: =IF('Detailed Results'!H81,"EXECUTED","UNAVAILABLE") | J14: =IF('Detailed Results'!H82,"EXECUTED","UNAVAILABLE")
A16: Coverage summary
A17: Model | B17: Planned | C17: Executed | D17: Unavailable | E17: Execution rate
A18: granite-3b | B18: =COUNTIF('Detailed Results'!$B$2:$B$82,A18) | C18: =COUNTIFS('Detailed Results'!$B$2:$B$82,A18,'Detailed Results'!$H$2:$H$82,TRUE) | D18: =B18-C18 | E18: =C18/B18
A19: granite-8b | B19: =COUNTIF('Detailed Results'!$B$2:$B$82,A19) | C19: =COUNTIFS('Detailed Results'!$B$2:$B$82,A19,'Detailed Results'!$H$2:$H$82,TRUE) | D19: =B19-C19 | E19: =C19/B19
A20: granite-30b | B20: =COUNTIF('Detailed Results'!$B$2:$B$82,A20) | C20: =COUNTIFS('Detailed Results'!$B$2:$B$82,A20,'Detailed Results'!$H$2:$H$82,TRUE) | D20: =B20-C20 | E20: =C20/B20

Sheet Methodology
A1: Methodology, Provenance and Required Caveats
A3: This sheet defines how the workbook should be interpreted and provides traceable source references.
A5: Campaign identity
A6: Campaign | B6: OpenVINO experimental fork campaign fv6
A7: Quality prompt set | B7: OPENVINO-SECTOR-EXPERIENCE-QUALITY-v3
A8: As-of date | B8: 2026-08-30
A9: Fork URL | B9: https://github.com/EgorDuplensky/openvino.git
A10: Fork branch | B10: turbo_quant
A11: Fork commit | B11: 1827f6458d049de11c1a8203c793af67c99935dc
A12: Runtime build | B12: 2026.2.0-1-1827f6458d0-turbo_quant
A13: Metric definitions
A14: Decode TPS | B14: 1000 / mean time-per-output-token in milliseconds; higher is better.
A15: TTFT sec | B15: Mean time to first token converted from milliseconds to seconds; lower is better.
A16: Peak RAM GB | B16: Maximum peak working-set measurement across the three benchmark repetitions, divided by 1024.
A17: Quality /10 | B17: Arithmetic mean of 48 objective prompts: healthcare 16, education 16, statistics 8, and general controls 8. Ten means full benchmark compliance, not ChatGPT equivalence or universal intelligence.
A18: Atomic scoring | B18: Each prompt has three declared checks worth 5, 3, and 2 points. More important factual, numerical, or safety requirements therefore contribute more than supporting details.
A19: Output-health gate | B19: Empty output, a repeated-character run of 16 or more, or punctuation ratio above 0.50 invalidates the output and awards zero criterion points.
A20: Prompt handling | B20: Quality uses deterministic greedy decoding and the chat template; prompt length is balanced at 16 short, 16 medium, and 16 long prompts. Performance timing retains the original plain-prompt path.
A21: Benchmark selection | B21: Median decode TPS among three executed repetitions; the entire selected repetition supplies latency metrics.
A23: Scope and limitations
A24: Executed artifacts | B24: Granite 3B INT4, Granite 3B INT8, and Granite 8B INT4.
A25: Unavailable artifacts | B25: Granite 3B FP16; Granite 8B INT8/FP16; all Granite 30B weights.
A26: 30B procedure | B26: The matrix begins with INT4 + TurboQuant 3-bit, but model acquisition is terminal because no validated 30B OpenVINO artifact was available within the machine resource/storage envelope.
A27: Quality caveat | B27: Scores measure compliance with exact published evidence checks. Valid synonyms not listed by a criterion can lose credit, so small differences should not be treated as definitive general-quality gaps.
A28: Artifact distinction | B28: FP16 weights for 3B and INT8/FP16 weights for 8B were unavailable. This is separate from the F16 KV-cache format, which did execute on available weights.
A29: Run continuity | B29: Model/weight/cache matrix, cache order, isolated processes, three benchmark repetitions, 32 benchmark tokens, and 128 quality tokens match the prior campaign approach.
A31: Source files and integrity
A32: experimental-openvino-detailed-results.csv | B32: 2f57390980664a79cdcc2272152fd316cd315360afd5ab3b715bba9fd70ebc9f
A33: experimental-openvino-comparison.csv | B33: 016d9424a7c43a6d2f5ea8ea97b51e1de83ec0ac4c0d3946bc52de1c8bdcdf09
A34: experimental-openvino-coverage.csv | B34: ebf8a9685beeec40e487e37365cde5de20ea57f64dd7c3948d5751926e983ccc
A35: experimental-openvino-quality-details.csv | B35: 834c2caa9c7eecc89043078ffbd9bba2b637b2ed82be8d412c6011c7f7fd978e
A36: Source folder | B36: experiments/raw-results/openvino-experimental-fork/2026-08-30/fv6
A37: Workbook validation | B37: 81 unique planned cases; 27 executed; 54 unavailable; 1,296 prompt runs; 3,888 atomic criterion rows; raw hashes, repetitions, prompt counts, and recomputed means reconciled with zero audit errors.

Sheet Source Data
A1: Detailed CSV - exact text snapshot | AI1: Comparison CSV - exact text snapshot | AV1: Coverage CSV - exact text snapshot
A2: case_id | B2: model | C2: weight_precision | D2: cache_codec | E2: key_cache_codec | F2: value_cache_codec | G2: status | H2: executed | I2: failure_stage | J2: failure_reason | K2: model_path | L2: model_sha256 | M2: model_size_bytes | N2: fork_url | O2: fork_branch | P2: fork_commit | Q2: context_tokens | R2: max_new_tokens | S2: load_ms | T2: ttft_ms | U2: prompt_tps | V2: tpot_ms | W2: decode_tps | X2: generation_duration_ms | Y2: peak_working_set_mb | Z2: peak_private_mb | AA2: available_ram_min_mb | AB2: kv_mb | AC2: quality_score | AD2: quality_prompt_count | AE2: raw_result_path | AF2: raw_result_sha256 | AI2: model | AJ2: weight_precision | AK2: cache_codec | AL2: status | AM2: executed | AN2: decode_tps | AO2: ttft_ms | AP2: peak_working_set_mb | AQ2: kv_mb | AR2: quality_score | AS2: failure_reason | AV2: model | AW2: planned_cases | AX2: recorded_cases | AY2: executed_cases | AZ2: quality_cases | BA2: terminal_cases | BB2: missing_cases
A3: granite-3b__int4__tbq3 | B3: granite-3b | C3: int4 | D3: tbq3 | E3: tbq3 | F3: tbq3 | G3: passed | H3: true | K3: external/models/openvino/granite-4.1-3b-int4-cw-ov-ea0231a | L3: 6da1029abd4a1464a94a571ac6a6a950c262b226c15912915a721e0643f7c708 | M3: 1832903073 | N3: https://github.com/EgorDuplensky/openvino.git | O3: turbo_quant | P3: 1827f6458d049de11c1a8203c793af67c99935dc | Q3: 24 | R3: 32 | S3: 1723.0 | T3: 5937.23291 | V3: 56.203629 | W3: 17.792446 | X3: 7679.960938 | Y3: 3632.773 | Z3: 1911.199 | AA3: 6709.723 | AC3: 5.2083 | AD3: 48 | AE3: experiments\raw-results\openvino-experimental-fork\2026-08-30\fv6\raw\granite-3b__int4__tbq3.json | AF3: a766b4ce3d4c1ba952e0ecf66568257ee28c779f7031332977e207875a0dca18 | AI3: granite-3b | AJ3: int4 | AK3: tbq3 | AL3: passed | AM3: true | AN3: 17.792446 | AO3: 5937.23291 | AP3: 3632.773 | AR3: 5.2083 | AV3: granite-3b | AW3: 27 | AX3: 27 | AY3: 18 | AZ3: 18 | BA3: 9 | BB3: 0
A4: granite-3b__int8__tbq3 | B4: granite-3b | C4: int8 | D4: tbq3 | E4: tbq3 | F4: tbq3 | G4: passed | H4: true | K4: external/models/openvino/granite-4.1-3b-int8-ov-f858c9e | L4: f92a009e300ee1c01edc8a6cbaf4f591e2998421757ce63c090d75a5687faa06 | M4: 3406770593 | N4: https://github.com/EgorDuplensky/openvino.git | O4: turbo_quant | P4: 1827f6458d049de11c1a8203c793af67c99935dc | Q4: 24 | R4: 32 | S4: 1807.0 | T4: 1042.16748 | V4: 102.076691 | W4: 9.796556 | X4: 4207.030762 | Y4: 6639.477 | Z4: 3423.484 | AA4: 3852.73 | AC4: 5.75 | AD4: 48 | AE4: experiments\raw-results\openvino-experimental-fork\2026-08-30\fv6\raw\granite-3b__int8__tbq3.json | AF4: 39d9aff18ec6589dce59598e0f1ba14ce8c65c86ea79dba2a7eb74ce17f321c7 | AI4: granite-3b | AJ4: int8 | AK4: tbq3 | AL4: passed | AM4: true | AN4: 9.796556 | AO4: 1042.16748 | AP4: 6639.477 | AR4: 5.75 | AV4: granite-8b | AW4: 27 | AX4: 27 | AY4: 9 | AZ4: 9 | BA4: 18 | BB4: 0
A5: granite-3b__fp16__tbq3 | B5: granite-3b | C5: fp16 | D5: tbq3 | E5: tbq3 | F5: tbq3 | G5: model_artifact_unavailable | H5: false | I5: model_acquisition | J5: no validated OpenVINO artifact supplied for granite-3b fp16 | N5: https://github.com/EgorDuplensky/openvino.git | O5: turbo_quant | P5: 1827f6458d049de11c1a8203c793af67c99935dc | AI5: granite-3b | AJ5: fp16 | AK5: tbq3 | AL5: model_artifact_unavailable | AM5: false | AS5: no validated OpenVINO artifact supplied for granite-3b fp16 | AV5: granite-30b | AW5: 27 | AX5: 27 | AY5: 0 | AZ5: 0 | BA5: 27 | BB5: 0
